Workbook

Sheet Калькулятор
A1: Тип изделия
A3: Тип изделия | B3: Фланец поворотный
A4: Параметры детали | D4: Параметры заготовки
A5: =INDEX(Таблица2[],ROW()-4,MATCH($B$3,'Параметры изделий'!$1:$1,0)) -> Внешний диметр | B5: 260 | D5: =INDEX(Таблица4[],ROW()-4,MATCH($B$3,'Параметры заготовки'!$1:$1,0)) -> Внешний диаметр | E5: 315
A6: =INDEX(Таблица2[],ROW()-4,MATCH($B$3,'Параметры изделий'!$1:$1,0)) -> 0 | B6: 200 | D6: =INDEX(Таблица4[],ROW()-4,MATCH($B$3,'Параметры заготовки'!$1:$1,0)) -> Внутренний диаметр | E6: 150
A7: =INDEX(Таблица2[],ROW()-4,MATCH($B$3,'Параметры изделий'!$1:$1,0)) -> 0 | B7: 50 | D7: =INDEX(Таблица4[],ROW()-4,MATCH($B$3,'Параметры заготовки'!$1:$1,0)) -> Толщина листа | E7: 70
A8: =INDEX(Таблица2[],ROW()-4,MATCH($B$3,'Параметры изделий'!$1:$1,0)) -> 0 | B8: 220 | D8: =INDEX(Таблица4[],ROW()-4,MATCH($B$3,'Параметры заготовки'!$1:$1,0)) -> #REF!
A9: =INDEX(Таблица2[],ROW()-4,MATCH($B$3,'Параметры изделий'!$1:$1,0)) -> 0 | B9: 10 | D9: =INDEX(Таблица4[],ROW()-4,MATCH($B$3,'Параметры заготовки'!$1:$1,0)) -> #REF!
A10: =INDEX(Таблица2[],ROW()-4,MATCH($B$3,'Параметры изделий'!$1:$1,0)) -> 0 | B10: 230 | D10: =INDEX(Таблица4[],ROW()-4,MATCH($B$3,'Параметры заготовки'!$1:$1,0)) -> #REF!
A11: =INDEX(Таблица2[],ROW()-4,MATCH($B$3,'Параметры изделий'!$1:$1,0)) -> 0 | B11: 45 | D11: =INDEX(Таблица4[],ROW()-4,MATCH($B$3,'Параметры заготовки'!$1:$1,0)) -> #REF!
A12: =INDEX(Таблица2[],ROW()-4,MATCH($B$3,'Параметры изделий'!$1:$1,0)) -> 0 | B12: 2 | D12: =INDEX(Таблица4[],ROW()-4,MATCH($B$3,'Параметры заготовки'!$1:$1,0)) -> #REF!
A13: =INDEX(Таблица2[],ROW()-4,MATCH($B$3,'Параметры изделий'!$1:$1,0)) -> 0 | B13: 45 | D13: =INDEX(Таблица4[],ROW()-4,MATCH($B$3,'Параметры заготовки'!$1:$1,0)) -> #REF!
A14: =INDEX(Таблица2[],ROW()-4,MATCH($B$3,'Параметры изделий'!$1:$1,0)) -> 0 | B14: 5 | D14: =INDEX(Таблица4[],ROW()-4,MATCH($B$3,'Параметры заготовки'!$1:$1,0)) -> #REF!
A15: =INDEX(Таблица2[],ROW()-4,MATCH($B$3,'Параметры изделий'!$1:$1,0)) -> 0 | B15: 30 | D15: =INDEX(Таблица4[],ROW()-4,MATCH($B$3,'Параметры заготовки'!$1:$1,0)) -> #REF!
A16: =INDEX(Таблица2[],ROW()-4,MATCH($B$3,'Параметры изделий'!$1:$1,0)) -> 0 | D16: =INDEX(Таблица4[],ROW()-4,MATCH($B$3,'Параметры заготовки'!$1:$1,0)) -> #REF!
A17: =INDEX(Таблица2[],ROW()-4,MATCH($B$3,'Параметры изделий'!$1:$1,0)) -> 0 | D17: =INDEX(Таблица4[],ROW()-4,MATCH($B$3,'Параметры заготовки'!$1:$1,0)) -> #REF!
A18: =INDEX(Таблица2[],ROW()-4,MATCH($B$3,'Параметры изделий'!$1:$1,0)) -> #REF! | D18: =INDEX(Таблица4[],ROW()-4,MATCH($B$3,'Параметры заготовки'!$1:$1,0)) -> #REF!
A19: =INDEX(Таблица2[],ROW()-4,MATCH($B$3,'Параметры изделий'!$1:$1,0)) -> #REF! | D19: =INDEX(Таблица4[],ROW()-4,MATCH($B$3,'Параметры заготовки'!$1:$1,0)) -> #REF!
A20: =INDEX(Таблица2[],ROW()-4,MATCH($B$3,'Параметры изделий'!$1:$1,0)) -> #REF! | D20: =INDEX(Таблица4[],ROW()-4,MATCH($B$3,'Параметры заготовки'!$1:$1,0)) -> #REF!
A21: =INDEX(Таблица2[],ROW()-4,MATCH($B$3,'Параметры изделий'!$1:$1,0)) -> #REF! | D21: =INDEX(Таблица4[],ROW()-4,MATCH($B$3,'Параметры заготовки'!$1:$1,0)) -> #REF!
A22: =INDEX(Таблица2[],ROW()-4,MATCH($B$3,'Параметры изделий'!$1:$1,0)) -> #REF! | D22: =INDEX(Таблица4[],ROW()-4,MATCH($B$3,'Параметры заготовки'!$1:$1,0)) -> #REF!

Sheet Типы станков
A1: Режим | B1: 16К20 | C1: 1М63 | D1: 1М65 | E1: Столбец5 | F1: Столбец6 | G1: Столбец7
A2: Сием поперечное точение | B2: 3 | C2: 4 | D2: 7
A3: Сием продольное точение | B3: 2 | C3: 5 | D3: 6
A4: Сием продольное внутр. Точение | B4: 2 | C4: 5 | D4: 6
A5: Подача поперечная | B5: 10 | C5: 11 | D5: 12
A6: Подача продольная | B6: 0.5 | C6: 0.65 | D6: 2
A7: Подача продольная внутр. Точение | B7: 0.5 | C7: 1 | D7: 2
A8: Максимальный диаметр | B8: 250 | C8: 610 | D8: 800
A9: Скорость резания продольная мм/мин | B9: 15000 | C9: 15000 | D9: 15000 | E9: 15000 | F9: 15000 | G9: 15000
A10: Скорость резания поперечная мм/мин | B10: 15000 | C10: 15000 | D10: 15000 | E10: 15000 | F10: 15000 | G10: 15000
A11: Скорость резания фасок мм/мин | B11: 15000 | C11: 15000 | D11: 15000 | E11: 15000 | F11: 15000 | G11: 15000
A12: Обороты шпинделя

Sheet Лист2
A1: получаем данные | B1: Значения | C1: расчет
A2: Разница диаметров
A3: Количество проходов торцовки
A4: Габарит детали
A5: Диаметр проточки
A6: Глубина проточки
A7: Размер фаски
A8: тип станка
A9: Длина

Sheet Получение данных для расчета
A1: Глубина внешнего точения (D1-D) | B1: =INDEX(Калькулятор!E5:E22,MATCH("Внешний диаметр (D1)",Калькулятор!D5:D22,0),1)-INDEX(Калькулятор!B5:B22,MATCH("Внешний диметр (D)",Калькулятор!A5:A22,0),1) -> #N/A | C1: Фланец приварной ТНФ
A2: Глубина торцовки (S-t) | B2: =INDEX(Калькулятор!E5:E22,MATCH("Толщина листа (S)",Калькулятор!D5:D22,0),1)-INDEX(Калькулятор!B5:B22,MATCH("Габарит детали (t)",Калькулятор!A5:A22,0),1) -> #N/A | C2: Фланец приварной ТНФ
A3: Длина торцовки (D1-D2) | B3: =INDEX(Калькулятор!E5:E22,MATCH("Внешний диаметр (D1)",Калькулятор!D5:D22,0),1)-INDEX(Калькулятор!E5:E22,MATCH("Внутренний диаметр (D2)",Калькулятор!D5:D22,0),1) -> #N/A | C3: Фланец приварной ТНФ
A4: Глубина внутреннего точения (d-D2) | B4: =INDEX(Калькулятор!B5:B22,MATCH("Внутренний диаметр (d)",Калькулятор!A5:A22,0),1)-INDEX(Калькулятор!E5:E22,MATCH("Внутренний диаметр (D2)",Калькулятор!D5:D22,0),1) -> #N/A | C4: Фланец приварной ТНФ
A5: Длина внутренней проточки (Dm-d) | B5: =INDEX(Калькулятор!B5:B22,MATCH("Диаметр проточки (DM)",Калькулятор!A5:A22,0),1)-INDEX(Калькулятор!B5:B22,MATCH("Внутренний диаметр (d)",Калькулятор!A5:A22,0),1) -> #N/A | C5: Фланец приварной ТНФ
A6: Глубина внутренней проточки (a) | B6: =INDEX(Калькулятор!B5:B22,MATCH("Глубина проточки (a)",Калькулятор!A5:A22,0),1) -> #N/A | C6: Фланец приварной ТНФ
A7: Размер фаски 1 (ch1) | B7: =IFERROR(INDEX(Калькулятор!B5:B22,MATCH("Размер фаски 1 (ch1)",Калькулятор!A5:A22,0),1),0) -> 0 | C7: Фланец приварной ТНФ
A8: Угол фаски (ch1) | B8: =INDEX(Калькулятор!B5:B22,MATCH("Угол фаски (ch1)",Калькулятор!A5:A22,0),1) -> #N/A | C8: Фланец приварной ТНФ
A9: Размер фаски 2 (ch2) | B9: =IFERROR(INDEX(Калькулятор!B5:B22,MATCH("Размер фаски 2 (ch2)",Калькулятор!A5:A22,0),1),0) -> 0 | C9: Фланец приварной ТНФ
A10: Угол фаски (ch2) | B10: =IFERROR(INDEX(Калькулятор!B5:B22,MATCH("Угол фаски (ch2)",Калькулятор!A5:A22,0),1),0) -> 0 | C10: Фланец приварной ТНФ
A11: Размер фаски 3 (ch3) | B11: =INDEX(Калькулятор!$B$5:$B$22,MATCH("Размер фаски 3 (ch3)",Калькулятор!$A$5:$A$22,0),1) -> #N/A | C11: Фланец приварной ТНФ
A12: Угол фаски (ch3) | B12: =INDEX(Калькулятор!B5:B22,MATCH("Угол фаски (ch3)",Калькулятор!A5:A22,0),1) -> #N/A | C12: Фланец приварной ТНФ
A13: Размер фаски 4 (ch4) | B13: =IFERROR(INDEX(Калькулятор!$B$5:$B$22,MATCH("Размер фаски 4 (ch4)",Калькулятор!$A$5:$A$22,0),1),0) -> 0
A14: Угол фаски (ch4)
A15: Размер фаски 5 (ch5) | B15: =IFERROR(INDEX(Калькулятор!$B$5:$B$22,MATCH("Размер фаски 5 (ch5)",Калькулятор!$A$5:$A$22,0),1),0) -> 0
A16: Угол фаски (ch5)
A17: Размер фаски 6 (ch6) | B17: =IFERROR(INDEX(Калькулятор!$B$5:$B$22,MATCH("Размер фаски 6 (ch6)",Калькулятор!$A$5:$A$22,0),1),0) -> 0
A18: Угол фаски (ch6)
A19: Размер фаски 7 (ch7) | B19: =IFERROR(INDEX(Калькулятор!$B$5:$B$22,MATCH("Размер фаски 7 (ch7)",Калькулятор!$A$5:$A$22,0),1),0) -> 0
A20: Угол фаски (ch7)
A21: Размер фаски 8 (ch8) | B21: =IFERROR(INDEX(Калькулятор!$B$5:$B$22,MATCH("Размер фаски 8 (ch8)",Калькулятор!$A$5:$A$22,0),1),0) -> 0
A22: Угол фаски (ch8)
A23: Размер фаски 9 (ch9) | B23: =IFERROR(INDEX(Калькулятор!$B$5:$B$22,MATCH("Размер фаски 9 (ch9)",Калькулятор!$A$5:$A$22,0),1),0) -> 0
A24: Угол фаски (ch9)
A25: Размер фаски 10 (ch10) | B25: =IFERROR(INDEX(Калькулятор!$B$5:$B$22,MATCH("Размер фаски 10 (ch10)",Калькулятор!$A$5:$A$22,0),1),0) -> 0
A26: Угол фаски (ch10)
A27: Длина 2-ой внутренней проточки (Dw-d) | B27: =IFERROR(INDEX(Калькулятор!B5:B22,MATCH("Диаметр 2-ой проточки (Dw)",Калькулятор!A5:A22,0),1)-INDEX(Калькулятор!B5:B22,MATCH("Внутренний диаметр (d)",Калькулятор!A5:A22,0),1),0) -> 0
A28: Глубина 2-ой внутренней проточки (t-b) | B28: =IFERROR(INDEX(Калькулятор!B5:B22,MATCH("Габарит детали (t)",Калькулятор!A5:A22,0),1)-INDEX(Калькулятор!B5:B22,MATCH("Глубина 2-ой проточки (b)",Калькулятор!A5:A22,0),1),0) -> 0
A29: Длина внешнего точения (S) | B29: =INDEX(Калькулятор!E5:E22,MATCH("Толщина листа (S)",Калькулятор!$D$5:$D$22,0),1) -> #N/A
A30: Длина внутреннего точения (t) | B30: =INDEX(Калькулятор!B5:B22,MATCH("Габарит детали (t)",Калькулятор!A5:A22,0),1) -> #N/A
A31: Количество витков при торцовке | B31: =B3/(2*(HLOOKUP('Получение данных для расчета'!B49,Таблица5[#All],MATCH("Сием поперечное точение",'Типы станков'!A1:A28,0) ))) -> #N/A
A32: Путь 1-го прохода торцовки | B32: =(3.14*B31*(INDEX(Калькулятор!E5:E22,MATCH("Внешний диаметр (D1)",Калькулятор!D5:D22,0),1)+INDEX(Калькулятор!E5:E22,MATCH("Внутренний диаметр (D2)",Калькулятор!D5:D22,0),1)))/2 -> #N/A
A33: Количество витков при 1-ой проточке | B33: =B5/(2*(HLOOKUP('Получение данных для расчета'!B49,Таблица5[#All],MATCH("Сием поперечное точение",'Типы станков'!A1:A28,0) ))) -> #N/A
A34: Путь 1-го прохода при 1-ой проточке | B34: =(3.14*B33*(INDEX(Калькулятор!B5:B22,MATCH("Диаметр проточки (DM)",Калькулятор!A5:A22,0),1)+INDEX(Калькулятор!B5:B22,MATCH("Внутренний диаметр (d)",Калькулятор!A5:A22,0),1)))/2 -> #N/A
A35: Количество витков при 2-ой проточке | B35: =B27/(2*(HLOOKUP('Получение данных для расчета'!B49,Таблица5[#All],MATCH("Сием поперечное точение",'Типы станков'!A1:A28,0) ))) -> #N/A | H35: =IFERROR(1,0) -> 1
A36: Путь 1-го прохода при 2-ой проточке | B36: =IFERROR((3.14*B35*(INDEX(Калькулятор!B5:B22,MATCH("Диаметр 2-ой проточки (Dw)",Калькулятор!A5:A22,0),1)+INDEX(Калькулятор!B5:B22,MATCH("Внутренний диаметр (d)",Калькулятор!A5:A22,0),1)))/2,0) -> 0
A37: Количество шагов внешн. Диаметр | B37: =B29/HLOOKUP('Получение данных для расчета'!B49,Таблица5[#All],MATCH("Подача продольная ",'Типы станков'!A1:A28,0) ) -> #N/A
A38: Путь 1-го прохода внеш. Точения | B38: =(SQRT( HLOOKUP('Получение данных для расчета'!B49,Таблица5[#All],MATCH("Подача продольная ",'Типы станков'!A1:A28,0) )^2+(3.14*INDEX(Калькулятор!B5:B22,MATCH("Внешний диметр (D)",Калькулятор!A5:A22,0),1))^2))*B37 -> #N/A
A39: Количество шагов внутр. Диаметр | B39: =B30/HLOOKUP('Получение данных для расчета'!B49,Таблица5[#All],MATCH("Подача продольная ",'Типы станков'!A1:A28,0) ) -> #N/A
A40: Путь 1-го прохода внутр. Точения | B40: =(SQRT( HLOOKUP('Получение данных для расчета'!B49,Таблица5[#All],MATCH("Подача продольная ",'Типы станков'!A1:A28,0) )^2+(3.14*INDEX(Калькулятор!B5:B22,MATCH("Внутренний диаметр (d)",Калькулятор!A5:A22,0),1))^2))*B39 -> #N/A | D40: =HLOOKUP('Получение данных для расчета'!B49,Таблица5[#All],MATCH("Подача продольная ",'Типы станков'!A1:A28,0) ) -> #N/A
...

Sheet Лист3
A1: =MATCH("Внешний диметр (D)",Калькулятор!A5:A22,0) -> #N/A | B1: определяем позицию в списке
A2: =INDEX(Калькулятор!B5:B22,MATCH("Внешний диметр (D)",Калькулятор!A5:A22,0),1) -> #N/A | B2: Получаем значение
A3: =IF(INDEX(Калькулятор!B5:B22,MATCH("Внешний диметр (D)",Калькулятор!A5:A22,0),1)>250,IF(INDEX(Калькулятор!B5:B22,MATCH("Внешний диметр (D)",Калькулятор!A5:A22,0),1)>610,IF(INDEX(Калькулятор!B5:B22,MATCH("Внешний диметр (D)",Калькулятор!A5:A22,0),1)>800,"ошибка отсутствуют станки больших диаметров","1М65"),"1М63"),"16К20") -> #N/A | B3: Сравнение с таблицей и получение модели станка
A5: =ROUNDUP(3.2,0) -> 4
A19: =MATCH("16К20",'Типы станков'!1:1,1) -> 2
A20: =HLOOKUP(Таблица5[#Headers],Таблица5[#All],MATCH("Сием продольное точение",'Типы станков'!A1:A28,0) ) -> 6

Sheet Параметры заготовки
A1: Фланец поворотный | B1: Фланец приварной ТНФ | C1: Фланец приварной
A2: Внешний диаметр | B2: Внешний диаметр (D1) | C2: Внешний диаметр (D1)
A3: Внутренний диаметр | B3: Внутренний диаметр (D2) | C3: Внутренний диаметр (D2)
A4: Толщина листа | B4: Толщина листа (S) | C4: Толщина листа (S)

Sheet Параметры изделий
A1: Фланец приварной ТНФ | B1: Кольцо приварное | C1: Фланец приварной | D1: Фланец поворотный | E1: Фланец компенсатора | F1: Фланец формующий | G1: Обечайка | H1: Круг | I1: Фланец переходной
A2: Внешний диметр (D) | B2: Внешний диметр | C2: Внешний диметр (D) | D2: Внешний диметр | E2: Внешний диметр | F2: Внешний диметр | G2: Внешний диметр
A3: Внутренний диаметр (d) | C3: Внутренний диаметр (d)
A4: Габарит детали (t) | C4: Габарит детали (t)
A5: Диаметр проточки (DM) | C5: Диаметр проточки (DM)
A6: Глубина проточки (a) | C6: Глубина проточки (a)
A7: Размер фаски 1 (ch1) | C7: Диаметр 2-ой проточки (Dw)
A8: Угол фаски (ch1) | C8: Глубина 2-ой проточки (b)
A9: Размер фаски 2 (ch2) | C9: Размер фаски 1 (ch1)
A10: Угол фаски (ch2) | C10: Угол фаски (ch1)
A11: Размер фаски 3 (ch3) | C11: Размер фаски 2 (ch2)
A12: Угол фаски (ch3) | C12: Угол фаски (ch2)
C13: Размер фаски 3 (ch3)
C14: Угол фаски (ch3)

Sheet Типы изделий
A1: Тип изделия
A2: Кольцо приварное
A3: Круг
A4: Обечайка
A5: Фланец компенсатора
A6: Фланец переходной
A7: Фланец поворотный
A8: Фланец приварной
A9: Фланец приварной ТНФ
A10: Фланец формующий
